Workbook

Sheet README
A1: Nazariya: unit pricing and unit economics (all prices in ₹, excluding 18% GST)
A3: How to use: change any BLUE number on 'Inputs' or 'Plan12M'. Everything else is a formula and recalculates.
A4: Sheets: Inputs → UnitCost (what one unit costs us) → PriceList (what we charge, margin) → Plans (SaaS tiers) →
A5: Competitors (public price points with sources) → Plan12M (12-month revenue, costs, cash) → BreakEven.
A7: Measured on this app: stitching time per room (14.9 s), raw capture size (3.9 MB / room), published size (~1 MB / room).
A8: NOT measured yet: GPU minutes per 3D walkthrough (recon scripts have never run on a GPU), real visitor numbers,
A9: capturer productivity. Treat those as assumptions until the first 20 paid jobs.
A10: Competitor prices are public or third-party figures and often conflict; see the Confidence column.
A11: Built 2026-10-17 by tools/build_pricing.py.

Sheet Inputs
A1: Input | C1: Value | D1: Unit | E1: Source / confidence
A2: General
A3: Exchange rate | C3: 88 | D3: Planning assumption (same as research docs)
A4: GST on our invoices (not included in prices) | C4: 0.18 | D4: India GST on SaaS / services
A5: Rooms in a typical 2BHK tour | C5: 6 | D5: 2 bed + living + kitchen + 2 bath (research doc)
A6: Carpet area of a typical 2BHK | C6: 900 | D6: Assumption
A7: Processing & hosting (measured on this app)
A8: CPU time to stitch one 30-shot room | C8: 15 | D8: MEASURED: your room 'Hc' stitched in 14.9 s
A9: Overhead multiplier (tiles, thumbnails, retries) | C9: 2 | D9: Assumption
A10: Cloud CPU price | C10: 0.04 | D10: Assumption: typical on-demand cloud vCPU; verify with provider
A11: Raw capture kept per room (30 photos) | C11: 3.9 | D11: MEASURED: priv/capture/mt7wn6pvq9aj = 3.9 MB
A12: Depth points per room (depth mode only) | C12: 6 | D12: App limit is 8 MB per room
A13: Published files per room (panorama + tiles) | C13: 1 | D13: MEASURED: 29 MB for 30 published panoramas
A14: Months raw captures are kept | C14: 3 | D14: Policy (DPDP minimisation, PRODUCTION.md)
A15: Object storage (Cloudflare R2 Standard) | C15: 0.015 | D15: developers.cloudflare.com/r2/pricing (egress free)
A16: Storage read requests (R2 Class B) | C16: 0.36 | D16: developers.cloudflare.com/r2/pricing
A17: Visitor sessions per tour per month | C17: 300 | D17: Assumption: replace with real analytics
A18: File requests per visitor session | C18: 15 | D18: Assumption (tiles + JSON)
A19: 3D walkthrough (GPU)
A20: GPU rental (RTX 4090, RunPod Secure Cloud) | C20: 0.69 | D20: RunPod ~US$0.69 secure / ~0.34 community (third-party 2026 listings)
A21: GPU minutes per home walkthrough | C21: 40 | D21: Assumption: NOT measured, recon scripts never run on a GPU yet
A22: Retry / failed-run allowance | C22: 0.3 | D22: Assumption
A23: Walkthrough photos kept (dataset) | C23: 120 | D23: ~400 keyframes x 0.3 MB
A24: Published 3D scene size | C24: 40 | D24: Assumption (demo splats avg 4.5 MB per room)
A25: Done-for-you capture (our team shoots)
A26: Field capturer cost (salary + conveyance) | C26: 30000 | D26: Assumption: ₹25k salary + ₹5k travel (research doc)
A27: Homes one capturer shoots per day | C27: 4 | D27: Assumption: clustered localities
A28: Working days per month | C28: 24
A29: Local travel per visit | C29: 150 | D29: Assumption
A30: 360 camera (Insta360 X5) for hard rooms | C30: 54990 | D30: Insta360 X5 India launch price ₹54,990
A31: Captures per camera before replacement | C31: 600 | D31: Assumption
A32: Ops review time per home (hotspots, floor plan, QA) | C32: 30 | D32: Assumption
A33: Ops staff cost | C33: 250 | D33: Assumption
A34: Selling & payments
A35: Payment gateway fee | C35: 0.02 | D35: Assumption: ~2% standard Indian gateway rate; verify
A36: Sales commission on service deals | C36: 0.1 | D36: Policy proposal
A37: OTP SMS price | C37: 0.2 | D37: MSG91 ~₹0.15-0.25 (third-party 2026 comparisons)
A38: Logins per customer per month | C38: 15 | D38: Assumption
A39: Support cost, Starter customer | C39: 100 | D39: Assumption
A40: Support cost, Pro customer | C40: 400 | D40: Assumption
...

Sheet UnitCost
A1: Cost item | C1: ₹ | D1: Unit | E1: How
A2: Processing one room (CPU) | C2: =Inputs!$C$8*Inputs!$C$9/3600*Inputs!$C$10*Inputs!$C$3 | D2: CPU seconds x price
A3: Keeping raw photos + depth for the retention period | C3: =(Inputs!$C$11+Inputs!$C$12)/1024*Inputs!$C$15*Inputs!$C$14*Inputs!$C$3 | D3: MB -> GB x months
A4: Hosting one published room for a month | C4: =Inputs!$C$13/1024*Inputs!$C$15*Inputs!$C$3
A5: Delivering a tour to visitors for a month | C5: =Inputs!$C$17*Inputs!$C$18/1000000*Inputs!$C$16*Inputs!$C$3 | D5: Egress is free on R2
A6: One 360° room, self-captured, hosted 12 months | C6: =$C$2+$C$3+12*$C$4
A7: Home tour, self-captured (6 rooms), 12 months | C7: =Inputs!$C$5*$C$6+12*$C$5 | D7: Software cost is close to zero
A8: Capturer time per home | C8: =Inputs!$C$26/(Inputs!$C$27*Inputs!$C$28)
A9: Camera wear per home | C9: =Inputs!$C$30/Inputs!$C$31
A10: Ops review per home | C10: =Inputs!$C$32/60*Inputs!$C$33
A11: Home tour, done-for-you (we shoot), 12 months | C11: =$C$7+$C$8+Inputs!$C$29+$C$9+$C$10 | D11: People cost dominates
A12: GPU training for one 3D walkthrough | C12: =Inputs!$C$21/60*Inputs!$C$20*Inputs!$C$3*(1+Inputs!$C$22) | D12: Not yet measured
A13: Storing walkthrough dataset + 3D scene | C13: =(Inputs!$C$23*Inputs!$C$14+Inputs!$C$24*12)/1024*Inputs!$C$15*Inputs!$C$3
A14: 3D walkthrough, total direct cost | C14: =$C$12+$C$13
A15: Hosting one live home tour for a month | C15: =Inputs!$C$5*$C$4+$C$5
A16: Login SMS per customer per month | C16: =Inputs!$C$37*Inputs!$C$38

Sheet PriceList
A1: Product | B1: Unit | C1: Price ₹ (ex-GST) | D1: Direct cost ₹ | E1: Payment fee ₹ | F1: Sales commission ₹ | G1: Contribution ₹ | H1: Margin % | I1: Price incl. 18% GST ₹ | J1: ₹ per sq ft (2BHK) | K1: Notes
A2: DIY home tour (self-capture in app, ≤8 rooms, floor plan, embed, 12 months) | B2: per home / year | C2: 999 | D2: =UnitCost!$C$7 | E2: =C2*Inputs!$C$35 | F2: 0 | G2: =C2-D2-E2-F2 | H2: =G2/C2 | I2: =C2*(1+Inputs!$C$4) | J2: =C2/Inputs!$C$6 | K2: Brokers, owners, PG/co-living operators
A3: Extra room on a DIY tour | B3: per room | C3: 149 | D3: =UnitCost!$C$6 | E3: =C3*Inputs!$C$35 | F3: 0 | G3: =C3-D3-E3-F3 | H3: =G3/C3 | I3: =C3*(1+Inputs!$C$4)
A4: Done-for-you home tour (we shoot, up to 3BHK) | B4: per home | C4: 4999 | D4: =UnitCost!$C$11 | E4: =C4*Inputs!$C$35 | F4: =C4*Inputs!$C$36 | G4: =C4-D4-E4-F4 | H4: =G4/C4 | I4: =C4*(1+Inputs!$C$4) | J4: =C4/Inputs!$C$6 | K4: Fast cash: brokers, builders' resale, rentals
A5: Done-for-you large home / villa (≤15 rooms) | B5: per home | C5: 9999 | D5: =2*UnitCost!$C$8+Inputs!$C$29+UnitCost!$C$9+2*UnitCost!$C$10+15*UnitCost!$C$6+12*UnitCost!$C$5 | E5: =C5*Inputs!$C$35 | F5: =C5*Inputs!$C$36 | G5: =C5-D5-E5-F5 | H5: =G5/C5 | I5: =C5*(1+Inputs!$C$4) | K5: Half-day shoot
A6: 3D walkthrough add-on (true 3D, GPU) | B6: per home | C6: 2999 | D6: =UnitCost!$C$14+UnitCost!$C$10 | E6: =C6*Inputs!$C$35 | F6: 0 | G6: =C6-D6-E6-F6 | H6: =G6/C6 | I6: =C6*(1+Inputs!$C$4) | K6: Only after GPU pipeline is validated
A7: Developer project package (≤4 unit types + amenities, white label, leads, 12 months) | B7: per project / year | C7: 49999 | D7: =5*UnitCost!$C$11+2*UnitCost!$C$14+12*Inputs!$C$41 | E7: =C7*Inputs!$C$35 | F7: =C7*Inputs!$C$36 | G7: =C7-D7-E7-F7 | H7: =G7/C7 | I7: =C7*(1+Inputs!$C$4) | K7: Sample flats + clubhouse; replaces site visits
A8: Hotel / resort package (≤10 room categories + lobby, 12 months) | B8: per property / year | C8: 24999 | D8: =2*UnitCost!$C$11+12*Inputs!$C$40 | E8: =C8*Inputs!$C$35 | F8: =C8*Inputs!$C$36 | G8: =C8-D8-E8-F8 | H8: =G8/C8 | I8: =C8*(1+Inputs!$C$4) | K8: OTA + website embed
A9: Hosting renewal, any tour | B9: per tour / year | C9: 499 | D9: =12*UnitCost!$C$15 | E9: =C9*Inputs!$C$35 | F9: 0 | G9: =C9-D9-E9-F9 | H9: =G9/C9 | I9: =C9*(1+Inputs!$C$4) | K9: Year 2 onwards

Sheet Plans
A1: Plan | B1: ₹ / month (ex-GST) | C1: ₹ / year (2 months free) | D1: Active tours | E1: Seats | F1: 3D walkthroughs / month | G1: Hosting ₹ | H1: Re-capture processing ₹ | I1: Login SMS ₹ | J1: 3D GPU ₹ | K1: Support ₹ | L1: Payment fee ₹ | M1: Cost / month ₹ | N1: Gross margin ₹ | O1: Gross margin % | P1: Features | Q1: Competitor anchor
A2: Starter | B2: 1499 | C2: =B2*10 | D2: 10 | E2: 1 | F2: 0 | G2: =D2*UnitCost!$C$15 | H2: =D2*Inputs!$C$43*Inputs!$C$5*(UnitCost!$C$2+UnitCost!$C$3) | I2: =E2*UnitCost!$C$16 | J2: =F2*UnitCost!$C$14 | K2: =Inputs!$C$39 | L2: =B2*Inputs!$C$35 | M2: =SUM(G2:L2) | N2: =B2-M2 | O2: =N2/B2 | P2: Self-capture, embeds, Nazariya branding | Q2: TeliportMe Essential US$19-25; Kuula Pro US$20
A3: Pro | B3: 4999 | C3: =B3*10 | D3: 50 | E3: 3 | F3: 1 | G3: =D3*UnitCost!$C$15 | H3: =D3*Inputs!$C$43*Inputs!$C$5*(UnitCost!$C$2+UnitCost!$C$3) | I3: =E3*UnitCost!$C$16 | J3: =F3*UnitCost!$C$14 | K3: =Inputs!$C$40 | L3: =B3*Inputs!$C$35 | M3: =SUM(G3:L3) | N3: =B3-M3 | O3: =N3/B3 | P3: White label, floor plans, depth mode, leads + analytics | Q3: TeliportMe Business US$29-35; Matterport Pro ~US$55-69
A4: Business | B4: 12999 | C4: =B4*10 | D4: 200 | E4: 10 | F4: 5 | G4: =D4*UnitCost!$C$15 | H4: =D4*Inputs!$C$43*Inputs!$C$5*(UnitCost!$C$2+UnitCost!$C$3) | I4: =E4*UnitCost!$C$16 | J4: =F4*UnitCost!$C$14 | K4: =Inputs!$C$41 | L4: =B4*Inputs!$C$35 | M4: =SUM(G4:L4) | N4: =B4-M4 | O4: =N4/B4 | P4: API, custom domain, 5 x 3D walkthroughs/month | Q4: TeliportMe Unlimited US$83-99; Matterport Business ~US$269-355
A5: Enterprise (from) | B5: 49999 | C5: =B5*10 | D5: 1000 | E5: 50 | F5: 20 | G5: =D5*UnitCost!$C$15 | H5: =D5*Inputs!$C$43*Inputs!$C$5*(UnitCost!$C$2+UnitCost!$C$3) | I5: =E5*UnitCost!$C$16 | J5: =F5*UnitCost!$C$14 | K5: =Inputs!$C$42 | L5: =B5*Inputs!$C$35 | M5: =SUM(G5:L5) | N5: =B5-M5 | O5: =N5/B5 | P5: SSO, SLA, dedicated success manager | Q5: Custom (all competitors)

Sheet Competitors
A1: Competitor | B1: Plan / unit | C1: US$ / month (low) | D1: US$ / month (high) | E1: ₹ / month (low) | F1: ₹ / month (high) | G1: What you get | H1: Source | I1: Confidence
A2: TeliportMe | B2: Essential | C2: 19 | D2: 25 | E2: =C2*Inputs!$C$3 | F2: =D2*Inputs!$C$3 | G2: Unlimited tours, 1 user | H2: https://teliportme.com/pricing (fetched 2026-10-17) | I2: Reported (two price sets shown; likely annual vs monthly)
A3: TeliportMe | B3: Business | C3: 29 | D3: 35 | E3: =C3*Inputs!$C$3 | F3: =D3*Inputs!$C$3 | G3: Unlimited tours, 3 users, 1 custom domain | H3: https://teliportme.com/pricing | I3: Reported
A4: TeliportMe | B4: Unlimited | C4: 83 | D4: 99 | E4: =C4*Inputs!$C$3 | F4: =D4*Inputs!$C$3 | G4: Unlimited users, 5 custom domains | H4: https://teliportme.com/pricing | I4: Reported
A5: Kuula | B5: Pro | C5: 20 | D5: 20 | E5: =C5*Inputs!$C$3 | F5: =D5*Inputs!$C$3 | G5: Unlimited uploads, tour editor | H5: https://www.capterra.com/p/179213/Kuula/pricing/ | I5: Reported (third-party)
A6: Kuula | B6: Business | C6: 36 | D6: 48 | E6: =C6*Inputs!$C$3 | F6: =D6*Inputs!$C$3 | G6: Analytics, password tours, custom domain | H6: Capterra / TrustRadius (conflict) | I6: Reported (third-party, conflicting)
A7: Matterport | B7: Starter | C7: 12 | D7: 14 | E7: =C7*Inputs!$C$3 | F7: =D7*Inputs!$C$3 | G7: 5-20 active spaces | H7: https://travvir.com/blog/en/matterport-pricing-explained | I7: Reported (third-party); Matterport plans page shows tiers only
A8: Matterport | B8: Professional | C8: 55 | D8: 69 | E8: =C8*Inputs!$C$3 | F8: =D8*Inputs!$C$3 | G8: 20-150 active spaces | H8: Third-party listings (conflict) | I8: Reported; possible Oct-2026 repricing unverified
A9: Matterport | B9: Business | C9: 269 | D9: 355 | E9: =C9*Inputs!$C$3 | F9: =D9*Inputs!$C$3 | G9: 100-300 active spaces | H9: Third-party listings (conflict) | I9: Reported
A11: Nucleus4D | B11: Per listing | G11: US$0.03 per sq ft per listing per year + dedicated capture rig | H11: Podcast summary (research ledger E11) | I11: Low confidence
A12: Indian 360 tour agency | B12: Per tour | G12: ₹1,00,000 per tour (one Ahmedabad vendor listing) | H12: https://m.indiamart.com/impcat/360-degree-virtual-tours.html | I12: Single asking price, not a market rate
A13: US 3D tour service | B13: Per small home | G13: US$100-500 | H13: https://www.styldod.com/blog/how-much-do-3d-virtual-tours-cost | I13: Reported

Sheet Plan12M
A1: Line | B1: Unit price ₹ | C1: Contribution / unit ₹ | D1: M1 | E1: M2 | F1: M3 | G1: M4 | H1: M5 | I1: M6 | J1: M7 | K1: M8 | L1: M9 | M1: M10 | N1: M11 | O1: M12 | P1: 12-month total
A2: VOLUMES (targets: edit the blue numbers)
A3: Done-for-you home tours sold | B3: =PriceList!$C$4 | C3: =PriceList!$G$4 | D3: 5 | E3: 10 | F3: 15 | G3: 20 | H3: 25 | I3: 30 | J3: 35 | K3: 40 | L3: 45 | M3: 50 | N3: 55 | O3: 60 | P3: =SUM(D3:O3)
A4: DIY home tours sold | B4: =PriceList!$C$2 | C4: =PriceList!$G$2 | D4: 0 | E4: 5 | F4: 10 | G4: 20 | H4: 30 | I4: 45 | J4: 60 | K4: 75 | L4: 90 | M4: 110 | N4: 130 | O4: 150 | P4: =SUM(D4:O4)
A5: Villas / large homes | B5: =PriceList!$C$5 | C5: =PriceList!$G$5 | D5: 0 | E5: 1 | F5: 1 | G5: 2 | H5: 2 | I5: 3 | J5: 3 | K5: 3 | L5: 4 | M5: 4 | N5: 4 | O5: 5 | P5: =SUM(D5:O5)
A6: 3D walkthrough add-ons | B6: =PriceList!$C$6 | C6: =PriceList!$G$6 | D6: 0 | E6: 0 | F6: 0 | G6: 1 | H6: 2 | I6: 3 | J6: 4 | K6: 5 | L6: 6 | M6: 7 | N6: 8 | O6: 9 | P6: =SUM(D6:O6)
A7: Developer project packages (new) | B7: =PriceList!$C$7 | C7: =PriceList!$G$7 | D7: 0 | E7: 0 | F7: 1 | G7: 1 | H7: 1 | I7: 2 | J7: 2 | K7: 2 | L7: 2 | M7: 3 | N7: 3 | O7: 3 | P7: =SUM(D7:O7)
A8: Hotel packages (new) | B8: =PriceList!$C$8 | C8: =PriceList!$G$8 | D8: 0 | E8: 1 | F8: 1 | G8: 1 | H8: 2 | I8: 2 | J8: 2 | K8: 2 | L8: 3 | M8: 3 | N8: 3 | O8: 3 | P8: =SUM(D8:O8)
A9: Starter subscribers (active) | B9: =Plans!$B$2 | C9: =Plans!$N$2 | D9: 0 | E9: 2 | F9: 4 | G9: 6 | H9: 9 | I9: 12 | J9: 15 | K9: 18 | L9: 21 | M9: 24 | N9: 27 | O9: 30 | P9: =SUM(D9:O9)
A10: Pro subscribers (active) | B10: =Plans!$B$3 | C10: =Plans!$N$3 | D10: 0 | E10: 0 | F10: 1 | G10: 2 | H10: 3 | I10: 4 | J10: 5 | K10: 6 | L10: 8 | M10: 9 | N10: 11 | O10: 12 | P10: =SUM(D10:O10)
A11: Business subscribers (active) | B11: =Plans!$B$4 | C11: =Plans!$N$4 | D11: 0 | E11: 0 | F11: 0 | G11: 0 | H11: 1 | I11: 1 | J11: 1 | K11: 2 | L11: 2 | M11: 2 | N11: 3 | O11: 3 | P11: =SUM(D11:O11)
A13: Revenue ₹ (ex-GST) | D13: =(D3*$B$3+D4*$B$4+D5*$B$5+D6*$B$6+D7*$B$7+D8*$B$8+D9*$B$9+D10*$B$10+D11*$B$11)*Inputs!$C$50 | E13: =(E3*$B$3+E4*$B$4+E5*$B$5+E6*$B$6+E7*$B$7+E8*$B$8+E9*$B$9+E10*$B$10+E11*$B$11)*Inputs!$C$50 | F13: =(F3*$B$3+F4*$B$4+F5*$B$5+F6*$B$6+F7*$B$7+F8*$B$8+F9*$B$9+F10*$B$10+F11*$B$11)*Inputs!$C$50 | G13: =(G3*$B$3+G4*$B$4+G5*$B$5+G6*$B$6+G7*$B$7+G8*$B$8+G9*$B$9+G10*$B$10+G11*$B$11)*Inputs!$C$50 | H13: =(H3*$B$3+H4*$B$4+H5*$B$5+H6*$B$6+H7*$B$7+H8*$B$8+H9*$B$9+H10*$B$10+H11*$B$11)*Inputs!$C$50 | I13: =(I3*$B$3+I4*$B$4+I5*$B$5+I6*$B$6+I7*$B$7+I8*$B$8+I9*$B$9+I10*$B$10+I11*$B$11)*Inputs!$C$50 | J13: =(J3*$B$3+J4*$B$4+J5*$B$5+J6*$B$6+J7*$B$7+J8*$B$8+J9*$B$9+J10*$B$10+J11*$B$11)*Inputs!$C$50 | K13: =(K3*$B$3+K4*$B$4+K5*$B$5+K6*$B$6+K7*$B$7+K8*$B$8+K9*$B$9+K10*$B$10+K11*$B$11)*Inputs!$C$50 | ... O13: =(O3*$B$3+O4*$B$4+O5*$B$5+O6*$B$6+O7*$B$7+O8*$B$8+O9*$B$9+O10*$B$10+O11*$B$11)*Inputs!$C$50 | P13: =SUM(D13:O13)
A14: Contribution ₹ (after direct costs, fees, commission) | D14: =(D3*$C$3+D4*$C$4+D5*$C$5+D6*$C$6+D7*$C$7+D8*$C$8+D9*$C$9+D10*$C$10+D11*$C$11)*Inputs!$C$50 | E14: =(E3*$C$3+E4*$C$4+E5*$C$5+E6*$C$6+E7*$C$7+E8*$C$8+E9*$C$9+E10*$C$10+E11*$C$11)*Inputs!$C$50 | F14: =(F3*$C$3+F4*$C$4+F5*$C$5+F6*$C$6+F7*$C$7+F8*$C$8+F9*$C$9+F10*$C$10+F11*$C$11)*Inputs!$C$50 | G14: =(G3*$C$3+G4*$C$4+G5*$C$5+G6*$C$6+G7*$C$7+G8*$C$8+G9*$C$9+G10*$C$10+G11*$C$11)*Inputs!$C$50 | H14: =(H3*$C$3+H4*$C$4+H5*$C$5+H6*$C$6+H7*$C$7+H8*$C$8+H9*$C$9+H10*$C$10+H11*$C$11)*Inputs!$C$50 | I14: =(I3*$C$3+I4*$C$4+I5*$C$5+I6*$C$6+I7*$C$7+I8*$C$8+I9*$C$9+I10*$C$10+I11*$C$11)*Inputs!$C$50 | J14: =(J3*$C$3+J4*$C$4+J5*$C$5+J6*$C$6+J7*$C$7+J8*$C$8+J9*$C$9+J10*$C$10+J11*$C$11)*Inputs!$C$50 | K14: =(K3*$C$3+K4*$C$4+K5*$C$5+K6*$C$6+K7*$C$7+K8*$C$8+K9*$C$9+K10*$C$10+K11*$C$11)*Inputs!$C$50 | ... O14: =(O3*$C$3+O4*$C$4+O5*$C$5+O6*$C$6+O7*$C$7+O8*$C$8+O9*$C$9+O10*$C$10+O11*$C$11)*Inputs!$C$50 | P14: =SUM(D14:O14)
A16: FIXED COSTS ₹ / month
A17: Cloud infrastructure | D17: =Inputs!$C$45 | E17: =Inputs!$C$45 | F17: =Inputs!$C$45 | G17: =Inputs!$C$45 | H17: =Inputs!$C$45 | I17: =Inputs!$C$45 | J17: =Inputs!$C$45 | K17: =Inputs!$C$45 | ... O17: =Inputs!$C$45 | P17: =SUM(D17:O17)
A18: Tools | D18: =Inputs!$C$46 | E18: =Inputs!$C$46 | F18: =Inputs!$C$46 | G18: =Inputs!$C$46 | H18: =Inputs!$C$46 | I18: =Inputs!$C$46 | J18: =Inputs!$C$46 | K18: =Inputs!$C$46 | ... O18: =Inputs!$C$46 | P18: =SUM(D18:O18)
A19: Accounting / compliance | D19: =Inputs!$C$47 | E19: =Inputs!$C$47 | F19: =Inputs!$C$47 | G19: =Inputs!$C$47 | H19: =Inputs!$C$47 | I19: =Inputs!$C$47 | J19: =Inputs!$C$47 | K19: =Inputs!$C$47 | ... O19: =Inputs!$C$47 | P19: =SUM(D19:O19)
A20: Marketing | D20: =Inputs!$C$48 | E20: =Inputs!$C$48 | F20: =Inputs!$C$48 | G20: =Inputs!$C$48 | H20: =Inputs!$C$48 | I20: =Inputs!$C$48 | J20: =Inputs!$C$48 | K20: =Inputs!$C$48 | ... O20: =Inputs!$C$48 | P20: =SUM(D20:O20)
A21: Sales / BD executive (+ commission above) | D21: 0 | E21: 35000 | F21: 35000 | G21: 35000 | H21: 35000 | I21: 35000 | J21: 35000 | K21: 35000 | L21: 35000 | M21: 35000 | N21: 35000 | O21: 35000 | P21: =SUM(D21:O21)
A22: Second sales executive | D22: 0 | E22: 0 | F22: 0 | G22: 0 | H22: 0 | I22: 35000 | J22: 35000 | K22: 35000 | L22: 35000 | M22: 35000 | N22: 35000 | O22: 35000 | P22: =SUM(D22:O22)
A23: Full-stack / 3D engineer (after grant or seed) | D23: 0 | E23: 0 | F23: 0 | G23: 0 | H23: 100000 | I23: 100000 | J23: 100000 | K23: 100000 | L23: 100000 | M23: 100000 | N23: 100000 | O23: 100000 | P23: =SUM(D23:O23)
A24: Ops lead (QA, onboarding, support) | D24: 0 | E24: 0 | F24: 0 | G24: 30000 | H24: 30000 | I24: 30000 | J24: 30000 | K24: 30000 | L24: 30000 | M24: 30000 | N24: 30000 | O24: 30000 | P24: =SUM(D24:O24)
A25: Total fixed costs ₹ | D25: =SUM(D17:D24) | E25: =SUM(E17:E24) | F25: =SUM(F17:F24) | G25: =SUM(G17:G24) | H25: =SUM(H17:H24) | I25: =SUM(I17:I24) | J25: =SUM(J17:J24) | K25: =SUM(K17:K24) | ... P25: =SUM(P17:P24)
A27: Monthly profit / (loss) ₹ | D27: =D14-D25 | E27: =E14-E25 | F27: =F14-F25 | G27: =G14-G25 | H27: =H14-H25 | I27: =I14-I25 | J27: =J14-J25 | K27: =K14-K25 | ... P27: =P14-P25
A28: Cash in bank ₹ (start + cumulative profit) | D28: =Inputs!$C$49+D27 | E28: =D28+E27 | F28: =E28+F27 | G28: =F28+G27 | H28: =G28+H27 | I28: =H28+I27 | J28: =I28+J27 | K28: =J28+K27 | L28: =K28+L27 | ... O28: =N28+O27
A29: Lowest cash point ₹ (negative = money you must raise first) | D29: =MIN(D28:O28)
A30: Field capturers needed (cost already in done-for-you price) | D30: =ROUNDUP((D3+D5*2)/(Inputs!$C$27*Inputs!$C$28),0) | E30: =ROUNDUP((E3+E5*2)/(Inputs!$C$27*Inputs!$C$28),0) | F30: =ROUNDUP((F3+F5*2)/(Inputs!$C$27*Inputs!$C$28),0) | G30: =ROUNDUP((G3+G5*2)/(Inputs!$C$27*Inputs!$C$28),0) | H30: =ROUNDUP((H3+H5*2)/(Inputs!$C$27*Inputs!$C$28),0) | I30: =ROUNDUP((I3+I5*2)/(Inputs!$C$27*Inputs!$C$28),0) | J30: =ROUNDUP((J3+J5*2)/(Inputs!$C$27*Inputs!$C$28),0) | K30: =ROUNDUP((K3+K5*2)/(Inputs!$C$27*Inputs!$C$28),0) | ... O30: =ROUNDUP((O3+O5*2)/(Inputs!$C$27*Inputs!$C$28),0)

Sheet BreakEven
A1: Question | C1: Answer | D1: Unit
A2: Fixed costs, lean (no salaries) | C2: =Inputs!$C$45+Inputs!$C$46+Inputs!$C$47+Inputs!$C$48
A3: Fixed costs with 2 sales + engineer + ops lead | C3: =$C$2+35000*2+100000+30000
A4: Done-for-you tours/month to cover lean costs | C4: =$C$2/PriceList!$G$4
A5: Done-for-you tours/month to cover full team | C5: =$C$3/PriceList!$G$4
A6: …or Pro subscribers to cover full team | C6: =$C$3/Plans!$N$3
A7: …or developer packages per month to cover full team | C7: =$C$3/PriceList!$G$7
A8: Homes one capturer can shoot per month | C8: =Inputs!$C$27*Inputs!$C$28
